<?xml version="1.0" encoding="utf-8"?>
<robot name="pi">
	<mujoco>
		<compiler meshdir="../meshes/" balanceinertia="true" discardvisual="false" />
	</mujoco>

	  <!-- [CAUTION] uncomment when convert to mujoco -->
  <!-- <link name="world"></link>
  <joint name="floating_base_joint" type="floating">
    <parent link="world" />
    <child link="base_link" />
  </joint> -->

	<link name="base_link">
		<inertial>
			<origin xyz="0.00071885 0.00002781 0.02370205" rpy="0 0 0" />
			<mass value="1.94350955" />
			<inertia ixx="0.01047683" ixy=" -0.00000234" ixz="0.00001204" iyy="0.01089441" iyz=" -0.00000484" izz="0.00389882" />
		</inertial>
		<visual>
			<origin xyz="0 0 0" rpy="0 0 0" />
			<geometry>
				<!-- <box size="0.1 0.1 0.1" /> -->
				<mesh filename="./meshes/baselink_1.STL" />
			</geometry>
			<material name="">
				<color rgba="1 1 1 1" />
			</material>
		</visual>
		<collision>
			<origin xyz="0 0 0.08" rpy="0 0 0" />
			<geometry>
				<box size="0.17 0.15 0.15" />
				<!-- <mesh filename="./meshes/base_link.STL" /> -->
			</geometry>
		</collision>
	</link>

<!-- left leg -->
	<link name="l_hip_pitch_link">
		<inertial>
			<origin xyz=" 0.00136864  0.03062518  0.00027130" rpy="0 0 0" />
			<mass value="0.39857633" />
			<inertia ixx=" 0.00010390" ixy="-0.00000206" ixz=" 0.00000007" iyy=" 0.00009707" iyz="-0.00000082" izz="0.00012422" />
		</inertial>
		<visual>
			<origin xyz="0 0 0" rpy="0 0 0" />
			<geometry>
				<mesh filename="./meshes/l_hip_pitch_link.STL" />
			</geometry>
			<material name="">
				<color rgba="0.75294 0.75294 0.75294 1" />
			</material>
		</visual>
		<collision>
			<origin xyz="0 0.06 0" rpy="0 0 0" />
			<geometry>
				<box size="0.05 0.05 0.05" />
				<!-- <mesh filename="./meshes/r_hip_pitch_link.STL" /> -->
			</geometry>
		</collision>
	</link>
	<joint name="07_l_hip_pitch_joint" type="revolute">
		<origin xyz="-5.1979E-05 0.0233 -0.033" rpy="0 0 0" />
		<parent link="base_link" />
		<child link="l_hip_pitch_link" />
		<axis xyz="0 1 0" />
		<limit lower="-1.5" upper="1.5" effort="20" velocity="5.45" />
		<dynamics damping="0.1" friction="0.0"/> <!-- 即使很小的阻尼也能极大改善稳定性 -->
	</joint>
	<link name="l_hip_roll_link">
		<inertial>
			<origin xyz="0.00098441 0.00013641 -0.06124949" rpy="0 0 0" />
			<mass value="0.48571832" />
			<inertia ixx=" 0.00048327" ixy="-0.00000044" ixz=" -0.00002100" iyy="0.00057415" iyz="0.00000082" izz="0.00022189" />
		</inertial>
		<visual>
			<origin xyz="0 0 0" rpy="0 0 0" />
			<geometry>
				<mesh filename="./meshes/l_hip_roll_link.STL" />
			</geometry>
			<material name="">
				<color rgba="0.75294 0.75294 0.75294 1" />
			</material>
		</visual>
		<collision>
			<origin xyz="0 0 0" rpy="0 0 0" />
			<geometry>
				<box size="0.001 0.001 0.001" />
				<!-- <mesh filename="./meshes/l_hip_roll_link.STL" /> -->
			</geometry>
		</collision>
	</link>
	<joint name="08_l_hip_roll_joint" type="revolute">
		<origin xyz="0 0.0568 0" rpy="0 0 0" />
		<parent link="l_hip_pitch_link" />
		<child link="l_hip_roll_link" />
		<axis xyz="1 0 0" />
		<limit lower="-0.38" upper="1.2" effort="20" velocity="5.45" />
		<dynamics damping="0.1" friction="0.0"/> <!-- 即使很小的阻尼也能极大改善稳定性 -->
	</joint>
	<link name="l_thigh_link">
		<inertial>
			<origin xyz="0.00000000 -0.00095496 -0.02368467" rpy="0 0 0" />
			<mass value=" 0.10937966" />
			<inertia ixx="0.00011979" ixy="0.00000000" ixz="0.00000000" iyy="0.00005743" iyz=" -0.00000427" izz="0.00009007" />
		</inertial>
		<visual>
			<origin xyz="0 0 0" rpy="0 0 0" />
			<geometry>
				<mesh filename="./meshes/l_thigh_link.STL" />
			</geometry>
			<material name="">
				<color rgba="0.75294 0.75294 0.75294 1" />
			</material>
		</visual>
		<collision>
			<origin xyz="0 0 0" rpy="0 0 0" />
			<geometry>
				<box size="0.001 0.001 0.001" />
				<!-- <mesh filename="./meshes/l_thigh_link.STL" /> -->
			</geometry>
		</collision>
	</link>
	<joint name="09_l_thigh_joint" type="revolute">
		<origin xyz="0 0 -0.06925" rpy="0 0 0" />
		<parent link="l_hip_roll_link" />
		<child link="l_thigh_link" />
		<axis xyz="0 0 1" />
		<limit lower="-1" upper="1" effort="20" velocity="5.45" />
		<dynamics damping="0.1" friction="0.0"/> <!-- 即使很小的阻尼也能极大改善稳定性 -->
	</joint>
	<link name="l_calf_link">
		<inertial>
			<origin xyz=" -0.00001362 0.00276237 -0.07005569" rpy="0 0 0" />
			<mass value="0.80286993" />
			<inertia ixx="0.00372685" ixy="-0.00000004" ixz=" -0.00001493" iyy="0.00371467" iyz="-0.00000110" izz="0.00018398" />
		</inertial>
		<visual>
			<origin xyz="0 0 0" rpy="0 0 0" />
			<geometry>
				<mesh filename="./meshes/l_calf_link.STL" />
			</geometry>
			<material name="">
				<color rgba="0.75294 0.75294 0.75294 1" />
			</material>
		</visual>
		<collision>
			<origin xyz="0 0 0" rpy="0 0 0" />
			<geometry>
				<box size="0.001 0.001 0.001" />
				<!-- <mesh filename="./meshes/l_calf_link.STL" /> -->
			</geometry>
		</collision>
	</link>
	<joint name="10_l_calf_joint" type="revolute">
		<origin xyz="0 0 -0.07025" rpy="0 0 0" />
		<parent link="l_thigh_link" />
		<child link="l_calf_link" />
		<axis xyz="0 1 0" />
		<limit lower="0" upper="2.2" effort="20" velocity="5.45" />
		<dynamics damping="0.1" friction="0.0"/> <!-- 即使很小的阻尼也能极大改善稳定性 -->
	</joint>
	<link name="l_ankle_pitch_link">
		<inertial>
			<origin xyz="0.00655369 -0.00218609 0.00001446" rpy="0 0 0" />
			<mass value=" 0.16558271" />
			<inertia ixx="0.00012024" ixy="-0.00000237" ixz="-0.00000008" iyy="0.00018462" iyz="0.00000000" izz="0.00027198" />
		</inertial>
		<visual>
			<origin xyz="0 0 0" rpy="0 0 0" />
			<geometry>
				<mesh filename="./meshes/l_ankle_pitch_link.STL" />
			</geometry>
			<material name="">
				<color rgba="0.75294 0.75294 0.75294 1" />
			</material>
		</visual>
		<collision>
			<origin xyz="0 0 0" rpy="0 0 0" />
			<geometry>
				<box size="0.07 0.065 0.045" />
				<!-- <mesh filename="./meshes/l_ankle_pitch_link.STL" /> -->
			</geometry>
		</collision>
	</link>
	<joint name="11_l_ankle_pitch_joint" type="revolute">
		<origin xyz="0 0 -0.14" rpy="0 0 0" />
		<parent link="l_calf_link" />
		<child link="l_ankle_pitch_link" />
		<axis xyz="0 1 0" />
		<limit lower="-0.8" upper="0.8" effort="20" velocity="5.45" />
		<dynamics damping="0.1" friction="0.0"/> <!-- 即使很小的阻尼也能极大改善稳定性 -->
	</joint>
	<link name="l_ankle_roll_link">
		<inertial>
			<origin xyz="0.00265784 0.00017568 -0.01266639" rpy="0 0 0" />
			<mass value="0.62234851" />
			<inertia ixx="0.00046403" ixy=" -0.00000236" ixz="-0.0002309" iyy="0.0014685" iyz=" -0.00000082" izz="0.0012907" />
		</inertial>
		<visual>
			<origin xyz="0 0 0" rpy="0 0 0" />
			<geometry>
				<mesh filename="./meshes/l_ankle_roll_link.STL" />
			</geometry>
			<material name="">
				<color rgba="0.75294 0.75294 0.75294 1" />
			</material>
		</visual>
		<collision>
			<origin xyz="0.036 -0.036 -0.0479" rpy="0 0 1.5708" />
			<geometry>
				<!-- <box size="0.17 0.07 0.008" /> -->
				<mesh filename="./meshes/foot.STL" scale="0.001 0.001 0.001"/>
			</geometry>
		</collision>
	</link>
	<joint name="12_l_ankle_roll_joint" type="revolute">
		<origin xyz="0.07525 0 0" rpy="0 0 0" />
		<parent link="l_ankle_pitch_link" />
		<child link="l_ankle_roll_link" />
		<axis xyz="1 0 0" />
		<limit lower="-0.6" upper="0.6" effort="20" velocity="5.45" />
		<dynamics damping="0.1" friction="0.0"/> <!-- 即使很小的阻尼也能极大改善稳定性 -->
	</joint>

<!-- right leg -->
	<link name="r_hip_pitch_link">
		<inertial>
			<origin xyz="0.00136979  -0.03116717 0.00027130" rpy="0 0 0" />
			<mass value=" 0.39857633" />
			<inertia ixx="0.00010524" ixy="0.00000180" ixz=" 0.00000007" iyy="0.00009707" iyz="-0.00000032" izz=" 0.00012556" />
		</inertial>
		<visual>
			<origin xyz="0 0 0" rpy="0 0 0" />
			<geometry>
				<mesh filename="./meshes/r_hip_pitch_link.STL" />
			</geometry>
			<material name="">
				<color rgba="0.75294 0.75294 0.75294 1" />
			</material>
		</visual>
		<collision>
			<origin xyz="0 -0.06 0" rpy="0 0 0" />
			<geometry>
				<box size="0.05 0.05 0.05" />
				<!-- <mesh filename="./meshes/r_hip_pitch_link.STL" /> -->
			</geometry>
		</collision>
	</link>
	<joint name="01_r_hip_pitch_joint" type="revolute">
		<origin xyz="-5.1979E-05 -0.0233 -0.033" rpy="0 0 0" />
		<parent link="base_link" />
		<child link="r_hip_pitch_link" />
		<axis xyz="0 1 0" />
		<limit lower="-1.5" upper="1.5" effort="20" velocity="5.45" />
		<dynamics damping="0.1" friction="0.0"/> <!-- 即使很小的阻尼也能极大改善稳定性 -->
	</joint>
	<link name="r_hip_roll_link">
		<inertial>
			<origin xyz=" 0.00098441 -0.03394577  -0.06124949" rpy="0 0 0" />
			<mass value="0.48571832" />
			<inertia ixx="0.00048327" ixy="-0.00000049" ixz="-0.00002100" iyy=" 0.00057415" iyz="-0.00000047" izz=" 0.00022190" />
		</inertial>
		<visual>
			<origin xyz="0 0 0" rpy="0 0 0" />
			<geometry>
				<mesh filename="./meshes/r_hip_roll_link.STL" />
			</geometry>
			<material name="">
				<color rgba="0.75294 0.75294 0.75294 1" />
			</material>
		</visual>
		<collision>
			<origin xyz="0 0 0" rpy="0 0 0" />
			<geometry>
				<box size="0.001 0.001 0.001" />
				<!-- <mesh filename="./meshes/r_hip_roll_link.STL" /> -->
			</geometry>
		</collision>
	</link>
	<joint name="02_r_hip_roll_joint" type="revolute">
		<origin xyz="0.00025 -0.0568 0" rpy="0 0 0" />
		<parent link="r_hip_pitch_link" />
		<child link="r_hip_roll_link" />
		<axis xyz="1 0 0" />
		<limit lower="-0.38" upper="1.2" effort="20" velocity="5.45" />
		<dynamics damping="0.1" friction="0.0"/> <!-- 即使很小的阻尼也能极大改善稳定性 -->
	</joint>
	<link name="r_thigh_link">
		<inertial>
			<origin xyz="0 0.00116854 -0.04755896" rpy="0 0 0" />
			<mass value="0.10937966" />
			<inertia ixx="0.00011940" ixy="0.00000000" ixz="0.00000000" iyy=" 0.00005743" iyz="0.00000410" izz=" 0.00008969" />
		</inertial>
		<visual>
			<origin xyz="0 0 0" rpy="0 0 0" />
			<geometry>
				<mesh filename="./meshes/r_thigh_link.STL" />
			</geometry>
			<material name="">
				<color rgba="0.75294 0.75294 0.75294 1" />
			</material>
		</visual>
		<collision>
			<origin xyz="0 0 0" rpy="0 0 0" />
			<geometry>
				<box size="0.001 0.001 0.001" />
				<!-- <mesh filename="./meshes/r_thigh_link.STL" /> -->
			</geometry>
		</collision>
	</link>
	<joint name="03_r_thigh_joint" type="revolute">
		<origin xyz="-0.00025 0 -0.06925" rpy="0 0 0" />
		<parent link="r_hip_roll_link" />
		<child link="r_thigh_link" />
		<axis xyz="0 0 1" />
		<limit lower="-1" upper="1" effort="20" velocity="5.45" />
		<dynamics damping="0.1" friction="0.0"/> <!-- 即使很小的阻尼也能极大改善稳定性 -->
	</joint>
	<link name="r_calf_link">
		<inertial>
			<origin xyz="-0.00001362 -0.00276237 -0.07005569" rpy="0 0 0" />
			<mass value="0.80286993" />
			<inertia ixx="0.00372685" ixy="0.00000004" ixz="0.00001494" iyy="0.00371467" iyz=" 0.00000110" izz="0.00018398" />
		</inertial>
		<visual>
			<origin xyz="0 0 0" rpy="0 0 0" />
			<geometry>
				<mesh filename="./meshes/r_calf_link.STL" />
			</geometry>
			<material name="">
				<color rgba="0.75294 0.75294 0.75294 1" />
			</material>
		</visual>
		<collision>
			<origin xyz="0 0 0" rpy="0 0 0" />
			<geometry>
				<box size="0.001 0.001 0.001" />
				<!-- <mesh filename="./meshes/r_calf_link.STL" /> -->
			</geometry>
		</collision>
	</link>
	<joint name="04_r_calf_joint" type="revolute">
		<origin xyz="0 -0.0027 -0.07025" rpy="0 0 0" />
		<parent link="r_thigh_link" />
		<child link="r_calf_link" />
		<axis xyz="0 1 0" />
		<limit lower="0" upper="2.2" effort="20" velocity="5.45" />
		<dynamics damping="0.1" friction="0.0"/> <!-- 即使很小的阻尼也能极大改善稳定性 -->
	</joint>
	<link name="r_ankle_pitch_link">
		<inertial>
			<origin xyz="0.00655369 0.00218609 -0.00001446" rpy="0 0 0" />
			<mass value="0.16558271" />
			<inertia ixx="0.00012024" ixy=" 0.00000237" ixz=" 0.00000008" iyy="0.00018462" iyz="0.00000000" izz="0.00027198" />
		</inertial>
		<visual>
			<origin xyz="0 0 0" rpy="0 0 0" />
			<geometry>
				<mesh filename="./meshes/r_ankle_pitch_link.STL" />
			</geometry>
			<material name="">
				<color rgba="0.75294 0.75294 0.75294 1" />
			</material>
		</visual>
		<collision>
			<origin xyz="0 0 0" rpy="0 0 0" />
			<geometry>
				<box size="0.07 0.065 0.045" />
				<!-- <mesh filename="./meshes/r_ankle_pitch_link.STL" /> -->
			</geometry>
		</collision>
	</link>
	<joint name="05_r_ankle_pitch_joint" type="revolute">
		<origin xyz="0 0 -0.14" rpy="0 0 0" />
		<parent link="r_calf_link" />
		<child link="r_ankle_pitch_link" />
		<axis xyz="0 1 0" />
		<limit lower="-0.8" upper="0.8" effort="20" velocity="5.45" />
		<dynamics damping="0.1" friction="0.0"/> <!-- 即使很小的阻尼也能极大改善稳定性 -->
	</joint>
	<link name="r_ankle_roll_link">
		<inertial>
			<origin xyz="0.00265784 0.00017568 -0.01266639" rpy="0 0 0" />
			<mass value="0.62234851" />
			<inertia ixx="0.00046403" ixy=" -0.00000236" ixz="-0.0002309" iyy="0.0014685" iyz=" -0.00000082" izz="0.0012907" />
		</inertial>
		<visual>
			<origin xyz="0 0 0" rpy="0 0 0" />
			<geometry>
				<mesh filename="./meshes/r_ankle_roll_link.STL" />
			</geometry>
			<material name="">
				<color rgba="0.75294 0.75294 0.75294 1" />
			</material>
		</visual>
		<collision>
			<origin xyz="0.036 -0.036 -0.0479" rpy="0 0 1.5708" />
			<geometry>
				<!-- <box size="0.17 0.07 0.008" /> -->
				<mesh filename="./meshes/foot.STL" scale="0.001 0.001 0.001"/>
			</geometry>
		</collision>
	</link>
	<joint name="06_r_ankle_roll_joint" type="revolute">
		<origin xyz="0.07525 0.0027 0" rpy="0 0 0" />
		<parent link="r_ankle_pitch_link" />
		<child link="r_ankle_roll_link" />
		<axis xyz="1 0 0" />
		<limit lower="-0.6" upper="0.6" effort="20" velocity="5.45" />
		<dynamics damping="0.1" friction="0.0"/> <!-- 即使很小的阻尼也能极大改善稳定性 -->
	</joint>
</robot>